<!--
 * @Author: 吴楚标
 * @Date: 2021-06-15 10:14:24
 * @LastEditors: 吴楚标
 * @LastEditTime: 2021-06-15 10:18:28
 * @Description: 
-->
<!DOCTYPE html>
<html lang="en">
<head>
  <meta charset="UTF-8">
  <meta http-equiv="X-UA-Compatible" content="IE=edge">
  <meta name="viewport" content="width=device-width, initial-scale=1.0">
  <title>关键问题-- 异常穿透</title>
</head>
<body>
  <script>
    //  异常穿透 在使用链式调用时，在最后指定失败的回调，前面任意环节出错，都会传到最后的失败回调
    let  p = new Promise((resolve, reject) => {
      setTimeout(() => {
        resolve('ok');
      }, 1000);
    });

    p.then(value => {
      throw 'error';
    }).then(value => {
      console.log(123);
    }).then(value => {
      console.log(321);
    }).catch(reason => {
      console.warn(reason);
    });
  </script>
</body>
</html>